#VRML_SIM R2025a utf8

EXTERNPROTO "https://raw.githubusercontent.com/cyberbotics/webots/R2025a/projects/objects/backgrounds/protos/TexturedBackground.proto"
EXTERNPROTO "https://raw.githubusercontent.com/cyberbotics/webots/R2025a/projects/objects/backgrounds/protos/TexturedBackgroundLight.proto"
EXTERNPROTO "https://raw.githubusercontent.com/cyberbotics/webots/R2025a/projects/objects/floors/protos/RectangleArena.proto"

WorldInfo {
}
Viewpoint {
  orientation 0.2453802067617505 -0.18426700138393276 -0.9517532381508004 4.6402247299932196
  position 0.019219358121159935 -1.4826958186441637 0.8228309699358218
}
TexturedBackground {
}
TexturedBackgroundLight {
}
RectangleArena {
}
Robot {
  translation -0.20102896777353157 0.1098535534109348 0.0388273414150244
  rotation -0.0033669975045569644 0.008107605030222346 -0.9999614642917387 -1.1701637595902392
  children [
    DEF GPS_SENSOR GPS {
      translation 0 0 0.05
      children [
        Shape {
          appearance PBRAppearance {
          }
          geometry Cylinder {
            height 0.1
            radius 0.05
          }
        }
      ]
      boundingObject Shape {
        appearance PBRAppearance {
        }
        geometry Cylinder {
          height 0.1
          radius 0.05
        }
      }
      physics Physics {
      }
    }
    DEF LIDAR_SENSOR Lidar {
      translation 0 0 0.05
      children [
        Shape {
          appearance PBRAppearance {
          }
          geometry Cylinder {
            height 0.1
            radius 0.05
          }
        }
      ]
      boundingObject Cylinder {
        height 0.1
        radius 0.1
      }
      physics Physics {
      }
      numberOfLayers 1
    }
    DEF BODY Shape {
      appearance PBRAppearance {
        baseColor 0.917647 0.145098 0.145098
        roughness 1
        metalness 0
      }
      geometry Box {
        size 0.2 0.1 0.05
      }
    }
    DEF WHEEL1 HingeJoint {
      jointParameters HingeJointParameters {
        position 1267.724990311295
        axis 0 1 0
        anchor 0.05 0.06 0
      }
      device [
        RotationalMotor {
          name "wheel1"
        }
      ]
      endPoint Solid {
        translation 0.05033662307054619 0.062285740787403676 7.038325618191579e-06
        rotation 0.6151633886417571 -0.5592832203634124 0.5556764208554481 2.0490316724619206
        children [
          DEF WHEEL Shape {
            appearance PBRAppearance {
              baseColor 0.305882 0.898039 0.25098
              roughness 1
              metalness 0
            }
            geometry Cylinder {
              height 0.02
              radius 0.04
              subdivision 24
            }
          }
        ]
        boundingObject USE WHEEL
        physics Physics {
        }
        linearVelocity 0.04622186663810846 0.10934340332878527 0.0002537782348164244
        angularVelocity -2.7477053298046576 1.1586501176375676 -0.006000865475550416
      }
    }
    DEF WHEEL2 HingeJoint {
      jointParameters HingeJointParameters {
        position 1830.061323087407
        axis 0 1 0
        anchor 0.05 -0.06 0
      }
      device [
        RotationalMotor {
          name "wheel2"
        }
      ]
      endPoint Solid {
        translation 0.050620321177669785 -0.06198301631149583 -0.0007296807108678238
        rotation -0.5533675428931217 -0.5845832145968993 0.5933353416778615 4.116574890969547
        children [
          USE WHEEL
        ]
        name "solid(1)"
        boundingObject USE WHEEL
        physics Physics {
        }
        linearVelocity 0.04535194324336493 0.10722048916029757 -0.00016893380632553977
        angularVelocity -2.747701660368531 1.1586475646793615 -0.00600120880291892
      }
    }
    DEF WHEEL3 HingeJoint {
      jointParameters HingeJointParameters {
        position 2533.146726388271
        axis 0 1 0
        anchor -0.05 0.06 0
      }
      device [
        RotationalMotor {
          name "wheel3"
        }
      ]
      endPoint Solid {
        translation -0.050090569905412795 0.061990126975082493 0.00040828002501526657
        rotation 0.7843332763153272 0.44170323493638824 -0.43556809331170554 1.819007938511291
        children [
          USE WHEEL
        ]
        name "solid(2)"
        boundingObject USE WHEEL
        physics Physics {
        }
        linearVelocity 0.046507817129475146 0.11024423090389429 -0.0001617733767702182
        angularVelocity -2.747716589565783 1.1586555707869117 -0.006000126124744307
      }
    }
    DEF WHEEL4 HingeJoint {
      jointParameters HingeJointParameters {
        position 1830.050682071239
        axis 0 1 0
        anchor -0.05 -0.06 0
      }
      device [
        RotationalMotor {
          name "wheel4"
        }
      ]
      endPoint Solid {
        translation -0.04999039036141475 -0.06233488455979619 0.000715566480563362
        rotation -0.557410123938463 -0.5826037839146222 0.5914953801165919 4.12286205970473
        children [
          USE WHEEL
        ]
        name "solid(3)"
        boundingObject USE WHEEL
        physics Physics {
        }
        linearVelocity 0.04688396859773251 0.1111156956421697 0.00016395514000783074
        angularVelocity -2.7477137701140286 1.1586545315805572 -0.005999866998247663
      }
    }
    DEF DS_RIGHT DistanceSensor {
      translation 0.1 -0.03 0
      rotation 0 0 1 -0.3
      children [
        Shape {
          appearance PBRAppearance {
            baseColor 0.184314 0.596078 0.847059
            roughness 1
            metalness 0
          }
          geometry Box {
            size 0.01 0.01 0.01
          }
        }
      ]
      name "ds_right"
    }
    DEF DS_LEFT DistanceSensor {
      translation 0.1 0.03 0
      rotation 0 0 1 0.3
      children [
        Shape {
          appearance PBRAppearance {
            baseColor 0.184314 0.596078 0.847059
            roughness 1
            metalness 0
          }
          geometry Box {
            size 0.01 0.01 0.01
          }
        }
      ]
      name "ds_left"
    }
  ]
  boundingObject USE BODY
  physics Physics {
    density -1
    mass 1
  }
  controller "controller"
  linearVelocity 0.045656158226212114 0.10857318650696617 0.0006579426404231946
  angularVelocity 0.01476506064381704 -0.011265367344775346 -0.0006993710730855482
}
