#VRML_SIM R2025a utf8

EXTERNPROTO "https://raw.githubusercontent.com/cyberbotics/webots/R2025a/projects/objects/backgrounds/protos/TexturedBackground.proto"
EXTERNPROTO "https://raw.githubusercontent.com/cyberbotics/webots/R2025a/projects/objects/backgrounds/protos/TexturedBackgroundLight.proto"
EXTERNPROTO "https://raw.githubusercontent.com/cyberbotics/webots/R2025a/projects/objects/floors/protos/RectangleArena.proto"
EXTERNPROTO "https://raw.githubusercontent.com/cyberbotics/webots/R2025a/projects/objects/apartment_structure/protos/Wall.proto"
EXTERNPROTO "https://raw.githubusercontent.com/cyberbotics/webots/R2025a/projects/objects/drinks/protos/BeerBottle.proto"

WorldInfo {
}
Viewpoint {
  orientation -0.37636400050348917 0.07307600110106251 0.9235854249543392 2.6333001764909643
  position 3.7581152909299833 -2.441538939702113 3.7348517338535996
}
TexturedBackground {
}
TexturedBackgroundLight {
}
RectangleArena {
  floorSize 3 3
}
Robot {
  translation 0.2845496026081429 0.06221997892151605 0.03909242042665308
  rotation -0.002823462925985884 -0.0027759269270563516 -0.9999921611126766 1.9416428352575383
  children [
    DEF GPS_SENSOR GPS {
      translation 0 0 0.05
      children [
        Shape {
          appearance PBRAppearance {
          }
          geometry Cylinder {
            height 0.1
            radius 0.05
          }
        }
      ]
      boundingObject Shape {
        appearance PBRAppearance {
        }
        geometry Cylinder {
          height 0.1
          radius 0.05
        }
      }
      physics Physics {
      }
    }
    DEF LIDAR_SENSOR Lidar {
      translation 0 0 0.05
      children [
        Shape {
          appearance PBRAppearance {
          }
          geometry Cylinder {
            height 0.1
            radius 0.05
          }
        }
      ]
      boundingObject Cylinder {
        height 0.1
        radius 0.1
      }
      physics Physics {
      }
      numberOfLayers 1
    }
    DEF BODY Shape {
      appearance PBRAppearance {
        baseColor 0.917647 0.145098 0.145098
        roughness 1
        metalness 0
      }
      geometry Box {
        size 0.2 0.1 0.05
      }
    }
    DEF WHEEL1 HingeJoint {
      jointParameters HingeJointParameters {
        position 1295.926754888951
        axis 0 1 0
        anchor 0.05 0.06 0
      }
      device [
        RotationalMotor {
          name "wheel1"
        }
      ]
      endPoint Solid {
        translation 0.049664773238439916 0.062285740787403676 -3.14268672538137e-05
        rotation 0.5685635015127084 0.5780948371396976 -0.585270795461413 2.1026567831030567
        children [
          DEF WHEEL Shape {
            appearance PBRAppearance {
              baseColor 0.305882 0.898039 0.25098
              roughness 1
              metalness 0
            }
            geometry Cylinder {
              height 0.02
              radius 0.04
              subdivision 24
            }
          }
        ]
        boundingObject USE WHEEL
        physics Physics {
        }
        linearVelocity -0.043299527912253055 -0.11343664999876989 0.0006234672428558584
        angularVelocity 2.802082047203353 -1.0802513074339843 0.009599849581428933
      }
    }
    DEF WHEEL2 HingeJoint {
      jointParameters HingeJointParameters {
        position 1842.9160400299284
        axis 0 1 0
        anchor 0.05 -0.06 0
      }
      device [
        RotationalMotor {
          name "wheel2"
        }
      ]
      endPoint Solid {
        translation 0.05038721421763695 -0.06198301631149583 -0.0008759551660547488
        rotation -0.4435140601582504 -0.6279782229624119 0.6394830958883239 3.9414341202034957
        children [
          USE WHEEL
        ]
        name "solid(1)"
        boundingObject USE WHEEL
        physics Physics {
        }
        linearVelocity -0.042739419295582295 -0.11189851682905662 -0.0005989801383262803
        angularVelocity 2.8020580695906525 -1.0802821951756585 0.009576139034478804
      }
    }
    DEF WHEEL3 HingeJoint {
      jointParameters HingeJointParameters {
        position 2561.3485103001517
        axis 0 1 0
        anchor -0.05 0.06 0
      }
      device [
        RotationalMotor {
          name "wheel3"
        }
      ]
      endPoint Solid {
        translation -0.04988007362149848 0.061990126975082493 -0.00040064092443540676
        rotation -0.33963983035924844 0.662593786211467 -0.6675434518497605 3.8059208152073816
        children [
          USE WHEEL
        ]
        name "solid(2)"
        boundingObject USE WHEEL
        physics Physics {
        }
        linearVelocity -0.0433639601136409 -0.11230985604401722 -0.0005025403643356665
        angularVelocity 2.8020813929901096 -1.0802555177474629 0.009599731948609453
      }
    }
    DEF WHEEL4 HingeJoint {
      jointParameters HingeJointParameters {
        position 1842.905398334384
        axis 0 1 0
        anchor -0.05 -0.06 0
      }
      device [
        RotationalMotor {
          name "wheel4"
        }
      ]
      endPoint Solid {
        translation -0.04978730390890504 -0.06233488455979619 0.0006832921089054799
        rotation -0.44750109954519773 -0.6265092083765296 0.638144950403318 3.9482165177266495
        children [
          USE WHEEL
        ]
        name "solid(3)"
        boundingObject USE WHEEL
        physics Physics {
        }
        linearVelocity -0.044878997527786325 -0.11605626244994384 0.0005222635127046535
        angularVelocity 2.802068384552876 -1.080289554323165 0.00957737919502866
      }
    }
    DEF DS_RIGHT DistanceSensor {
      translation 0.1 -0.03 0
      rotation 0 0 1 -0.3
      children [
        Shape {
          appearance PBRAppearance {
            baseColor 0.184314 0.596078 0.847059
            roughness 1
            metalness 0
          }
          geometry Box {
            size 0.01 0.01 0.01
          }
        }
      ]
      name "ds_right"
    }
    DEF DS_LEFT DistanceSensor {
      translation 0.1 0.03 0
      rotation 0 0 1 0.3
      children [
        Shape {
          appearance PBRAppearance {
            baseColor 0.184314 0.596078 0.847059
            roughness 1
            metalness 0
          }
          geometry Box {
            size 0.01 0.01 0.01
          }
        }
      ]
      name "ds_left"
    }
  ]
  boundingObject USE BODY
  physics Physics {
    density -1
    mass 1
  }
  controller "controller"
  linearVelocity -0.04344773888784196 -0.11409688689234249 0.00033574852778243687
  angularVelocity 0.006142009085131879 0.007276316972442149 0.005565835168074657
}
Wall {
  translation 0.02 -1.25 0
  name "wall(6)"
  size 0.1 0.5 0.2
}
Wall {
  translation 0.02 -0.75 0
  name "wall(7)"
  size 0.1 0.5 0.2
}
Wall {
  translation -0.56 -0.75 0
  name "wall(27)"
  size 0.1 0.5 0.2
}
Wall {
  translation -0.56 -1.23 0
  name "wall(28)"
  size 0.1 0.5 0.2
}
Wall {
  translation 0.95 -0.37 0
  name "wall(4)"
  size 0.1 0.5 0.2
}
Wall {
  translation 0.45 -0.32 0
  name "wall(8)"
  size 0.1 0.5 0.2
}
Wall {
  translation -0.56 0.64 0
  name "wall(14)"
  size 0.1 0.5 0.2
}
Wall {
  translation -1.05 0.08 0
  name "wall(22)"
  size 0.1 0.5 0.2
}
Wall {
  translation -1.05 -0.75 0
  name "wall(25)"
  size 0.1 0.5 0.2
}
Wall {
  translation -1.05 0.55 0
  name "wall(23)"
  size 0.1 0.5 0.2
}
Wall {
  translation -1.05 0.8 0
  name "wall(24)"
  size 0.1 0.5 0.2
}
Wall {
  translation -0.56 0.64 0
  name "wall(15)"
  size 0.1 0.5 0.2
}
Wall {
  translation 0.45 -0.32 0
  name "wall(11)"
  size 0.1 0.5 0.2
}
Wall {
  translation 0.95 1.26 0
  name "wall(9)"
  size 0.1 0.5 0.2
}
Wall {
  translation 0.34 1.22 0
  name "wall(18)"
  size 0.1 0.5 0.2
}
Wall {
  translation 0.95 1.13 0
  name "wall(10)"
  size 0.1 0.5 0.2
}
Wall {
  translation 1.24 -0.57 0
  rotation 0 0 1 1.5708
  name "wall(1)"
  size 0.1 0.5 0.2
}
Wall {
  translation 0.73 0.42 0
  rotation 0 0 1 1.5708
  name "wall(12)"
  size 0.1 0.5 0.2
}
Wall {
  translation 1.23 0.42 0
  rotation 0 0 1 1.5708
  name "wall(5)"
  size 0.1 0.5 0.2
}
Wall {
  translation 0.23 0.42 0
  rotation 0 0 1 1.5708
  name "wall(13)"
  size 0.1 0.5 0.2
}
Wall {
  translation 0.23 -0.12 0
  rotation 0 0 1 1.5708
  name "wall(19)"
  size 0.1 0.5 0.2
}
Wall {
  translation -0.27 -0.12 0
  rotation 0 0 1 1.5708
  name "wall(20)"
  size 0.1 0.5 0.2
}
Wall {
  translation -0.77 -0.55 0
  rotation 0 0 1 1.5708
  name "wall(26)"
  size 0.1 0.5 0.2
}
Wall {
  translation -0.77 -0.12 0
  rotation 0 0 1 1.5708
  name "wall(21)"
  size 0.1 0.5 0.2
}
Wall {
  translation -0.36 0.92 0
  rotation 0 0 1 1.5708
  name "wall(16)"
  size 0.1 0.5 0.2
}
Wall {
  translation 0.14 0.92 0
  rotation 0 0 1 1.5708
  name "wall(17)"
  size 0.1 0.5 0.2
}
Wall {
  translation 0.74 -1.02 0
  rotation 0 0 1 1.5708
  name "wall(2)"
  size 0.1 0.5 0.2
}
Wall {
  translation 0.25 -0.55 0
  rotation 0 0 1 1.5708
  name "wall(3)"
  size 0.1 0.5 0.2
}
BeerBottle {
  translation -0.34 -1.37 0
}
BeerBottle {
  translation -0.2 -1.37 0
  name "beer bottle(1)"
}
BeerBottle {
  translation -0.2 -1.37 0
  name "beer bottle(2)"
}
