#VRML_SIM R2025a utf8

EXTERNPROTO "https://raw.githubusercontent.com/cyberbotics/webots/R2025a/projects/objects/backgrounds/protos/TexturedBackground.proto"
EXTERNPROTO "https://raw.githubusercontent.com/cyberbotics/webots/R2025a/projects/objects/backgrounds/protos/TexturedBackgroundLight.proto"
EXTERNPROTO "https://raw.githubusercontent.com/cyberbotics/webots/R2025a/projects/objects/floors/protos/RectangleArena.proto"

WorldInfo {
}
Viewpoint {
  orientation -0.13261157195609735 0.8305129983099202 0.5409827452161475 0.5740350128037081
  position -6.538084991356148 -2.628197133399963 4.437876960711429
}
TexturedBackground {
}
TexturedBackgroundLight {
}
RectangleArena {
  translation 1.59215e-07 0 0.03
  rotation 0 1 0 5.30716e-06
  floorSize 4 4
}
DEF Obs1 Solid {
  translation 1.69565 -0.102897 0.142507
  rotation -0.0025754902978973823 0.002671230308971273 0.9999931156654838 -1.5881053071795863
  children [
    Shape {
      appearance PBRAppearance {
      }
      geometry Box {
        size 1 0.05 0.5
      }
    }
  ]
}
Robot {
  translation -1.6322659560478066 1.6593531017707346 0.06967792096506752
  rotation -0.0010183277964976977 0.0005157268911356028 0.9999993485169241 1.0041980038196072
  children [
    DEF gps GPS {
      translation -0.05 -0.02 0.03
      children [
        Shape {
          appearance PBRAppearance {
          }
          geometry Cylinder {
            height 0.02
            radius 0.02
          }
        }
      ]
      boundingObject Shape {
        appearance PBRAppearance {
        }
        geometry Cylinder {
          height 0.02
          radius 0.02
        }
      }
      physics Physics {
      }
    }
    DEF lidar Lidar {
      translation 0.07 -0.02 0.04
      children [
        Shape {
          appearance PBRAppearance {
          }
          geometry Cylinder {
            height 0.025
            radius 0.025
          }
        }
      ]
      boundingObject Shape {
        appearance PBRAppearance {
        }
        geometry Cylinder {
          height 0.025
          radius 0.025
        }
      }
      physics Physics {
      }
      horizontalResolution 128
      fieldOfView 3.14
      verticalFieldOfView 0.1
      numberOfLayers 1
    }
    DEF BODY Shape {
      appearance PBRAppearance {
        baseColor 0.917647 0.145098 0.145098
        roughness 1
        metalness 0
      }
      geometry Box {
        size 0.2 0.1 0.05
      }
    }
    DEF WHEEL1 HingeJoint {
      jointParameters HingeJointParameters {
        position 7791.7623215060175
        axis 0 1 0
        anchor 0.05 0.06 0
      }
      device [
        RotationalMotor {
          name "wheel1"
        }
      ]
      endPoint Solid {
        translation 0.0491036378748406 0.06043224674532349 0.00014453222688818213
        rotation 0.9141450953296006 0.2803376946411354 -0.29283019251458475 1.677751128897604
        children [
          DEF WHEEL Shape {
            appearance PBRAppearance {
              baseColor 0.305882 0.898039 0.25098
              roughness 1
              metalness 0
            }
            geometry Cylinder {
              height 0.02
              radius 0.04
              subdivision 24
            }
          }
        ]
        boundingObject USE WHEEL
        physics Physics {
        }
        linearVelocity 0.023351400243406945 0.010226756553395819 0.00023987701212793716
        angularVelocity -0.85272909395996 0.530826216229972 -0.3959831664841282
      }
    }
    DEF WHEEL2 HingeJoint {
      jointParameters HingeJointParameters {
        position 5595.597133622787
        axis 0 1 0
        anchor 0.05 -0.06 0
      }
      device [
        RotationalMotor {
          name "wheel2"
        }
      ]
      endPoint Solid {
        translation 0.050000503481600046 -0.06000008469764562 -2.1628182409459155e-06
        rotation 0.14925233082272601 -0.699185278558616 0.6991878774627703 2.8452764074089654
        children [
          USE WHEEL
        ]
        name "solid(1)"
        boundingObject USE WHEEL
        physics Physics {
        }
        linearVelocity -0.001693530222736819 -0.03030925393335026 -0.00022758625359027145
        angularVelocity 0.8414459509055369 -0.532152030290504 -0.3948497555941369
      }
    }
    DEF WHEEL3 HingeJoint {
      jointParameters HingeJointParameters {
        position 7791.762146579493
        axis 0 1 0
        anchor -0.05 0.06 0
      }
      device [
        RotationalMotor {
          name "wheel3"
        }
      ]
      endPoint Solid {
        translation -0.0500025620969371 0.060000084994313085 3.87233899254692e-06
        rotation -0.9129212348993375 -0.28859506699229864 0.28859609522233515 4.621405385382451
        children [
          USE WHEEL
        ]
        name "solid(2)"
        boundingObject USE WHEEL
        physics Physics {
        }
        linearVelocity -0.009920049087842922 0.030771684607070773 -0.00020924799152513839
        angularVelocity -0.8527280223665716 0.5308256033685186 -0.3959835092287362
      }
    }
    DEF WHEEL4 HingeJoint {
      jointParameters HingeJointParameters {
        position 5595.5965285584525
        axis 0 1 0
        anchor -0.05 -0.06 0
      }
      device [
        RotationalMotor {
          name "wheel4"
        }
      ]
      endPoint Solid {
        translation -0.0499992565947815 -0.05999991499841628 -1.9667672595152233e-06
        rotation 0.14903609693047895 -0.6992083389644722 0.6992109413719674 2.8456994698723994
        children [
          USE WHEEL
        ]
        name "solid(3)"
        boundingObject USE WHEEL
        physics Physics {
        }
        linearVelocity -0.035108143806601676 -0.009323113853432648 0.00020653221936763614
        angularVelocity 0.8414471979586795 -0.5321527796255322 -0.3948493888444333
      }
    }
    DEF DS_RIGHT DistanceSensor {
      translation 0.1 -0.03 0
      rotation 0 0 1 -0.3
      children [
        Shape {
          appearance PBRAppearance {
            baseColor 0.184314 0.596078 0.847059
            roughness 1
            metalness 0
          }
          geometry Box {
            size 0.01 0.01 0.01
          }
        }
      ]
      name "ds_right"
    }
    DEF DS_LEFT DistanceSensor {
      translation 0.1 0.03 0
      rotation 0 0 1 0.3
      children [
        Shape {
          appearance PBRAppearance {
            baseColor 0.184314 0.596078 0.847059
            roughness 1
            metalness 0
          }
          geometry Box {
            size 0.01 0.01 0.01
          }
        }
      ]
      name "ds_left"
    }
  ]
  boundingObject USE BODY
  physics Physics {
    density -1
    mass 1
  }
  controller "controlador"
  window "<none>"
  linearVelocity -0.005420475977070249 -0.0006449998968725398 -0.00022842457260992431
  angularVelocity -0.005636112225459461 -0.0006543914063449534 -0.39440447606293333
}
Solid {
  translation 0 -0.96 0
  children [
    Shape {
      appearance PBRAppearance {
      }
      geometry Box {
        size 0.9 0.05 0.6
      }
    }
  ]
  name "solid(1)"
}
Solid {
  translation 0 1.15 0.09
  children [
    Shape {
      appearance PBRAppearance {
      }
      geometry Box {
        size 2 0.05 0.6
      }
    }
  ]
  name "solid(2)"
}
